Workbook

Sheet Retail_Dataset
A1: Order ID | B1: Region | C1: Country | D1: Category | E1: Sales Channel | F1: Order Priority | G1: Order Date | H1: Units Sold | I1: Unit Price | J1: Unit Cost | K1: Total Revenue | L1: Missing Values Summary | P1: Region | Q1: Average Profit
A2: ORD0001 | B2: East | C2: Germany | D2: Beverages | E2: Online | F2: High | G2: 44927 | H2: 235 | I2: 152.92 | J2: 153.6 | K2: =H2*I2 -> 35936.2 | P2: East | Q2: {=SUMPRODUCT((B2:B351=P2)*((I2:I351-J2:J351)*H2:H351))/COUNTIF(B2:B351,P2)} -> 12492.87
A3: ORD0002 | B3: West | C3: India | D3: Food | E3: Online | F3: Low | G3: 44928 | H3: 341 | I3: 467.92 | J3: 139.84 | K3: =H3*I3 -> 159560.72 | L3: Column Name | M3: Missing Count | N3: Missing % | P3: West | Q3: {=SUMPRODUCT((B2:B351=P3)*((I2:I351-J2:J351)*H2:H351))/COUNTIF(B2:B351,P3)} -> 11221.35
A4: ORD0003 | B4: North | C4: India | D4: Clothing | E4: Offline | F4: High | G4: 44929 | H4: 179 | I4: 473.94 | J4: 97.14 | K4: =H4*I4 -> 84835.26 | L4: Order ID | M4: 0 | N4: 0 | P4: North | Q4: {=SUMPRODUCT((B2:B351=P4)*((I2:I351-J2:J351)*H2:H351))/COUNTIF(B2:B351,P4)} -> 16727.885
A5: ORD0004 | B5: East | C5: USA | D5: Furniture | E5: Offline | F5: Medium | G5: 44930 | H5: 18 | I5: 314.53 | J5: 204.87 | K5: =H5*I5 -> 5661.54 | L5: Region | M5: 10 | N5: 0.0286 | P5: South | Q5: {=SUMPRODUCT((B2:B351=P5)*((I2:I351-J2:J351)*H2:H351))/COUNTIF(B2:B351,P5)} -> 19174.705
A6: ORD0005 | B6: East | C6: India | D6: Furniture | E6: Offline | F6: Medium | G6: 44931 | H6: 472 | I6: 392.79 | J6: 330.46 | K6: =H6*I6 -> 185396.88 | L6: Country | M6: 0 | N6: 0
A7: ORD0006 | B7: West | C7: UK | D7: Clothing | E7: Online | F7: High | G7: 44932 | H7: 49 | I7: 308.07 | J7: 113.32 | K7: =H7*I7 -> 15095.43 | L7: Category | M7: 10 | N7: 0.0286
A8: ORD0007 | B8: North | C8: Germany | D8: Clothing | E8: Online | F8: Low | G8: 44933 | H8: 34 | I8: 244.78 | J8: 377.07 | K8: =H8*I8 -> 8322.52 | L8: Sales Channel | M8: 0 | N8: 0
A9: ORD0008 | B9: North | C9: India | D9: Beverages | E9: Online | F9: High | G9: 44934 | H9: 270 | I9: 332.11 | J9: 349.59 | K9: =H9*I9 -> 89669.7 | L9: Order Priority | M9: 0 | N9: 0
A10: ORD0009 | B10: East | C10: India | D10: Beverages | E10: Online | F10: Low | G10: 44935 | H10: 404 | I10: 278.74 | J10: 66.38 | K10: =H10*I10 -> 112610.96 | L10: Order Date | M10: 0 | N10: 0
A11: ORD0010 | B11: West | C11: USA | D11: Furniture | E11: Online | F11: Medium | G11: 44936 | H11: 452 | I11: 300.75 | J11: 314.94 | K11: =H11*I11 -> 135939 | L11: Units Sold | M11: 10 | N11: 0.0286
A12: ORD0011 | B12: East | C12: USA | D12: Food | E12: Online | F12: Low | G12: 44937 | H12: 235 | I12: 393 | J12: 230.69 | K12: =H12*I12 -> 92355 | L12: Unit Price | M12: 10 | N12: 0.0286
A13: ORD0012 | B13: East | C13: UK | D13: Furniture | E13: Offline | F13: Medium | G13: 44938 | H13: 481 | I13: 243.05 | J13: 227.5 | K13: =H13*I13 -> 116907.05 | L13: Unit Cost | M13: 0 | N13: 0
A14: ORD0013 | B14: East | C14: Germany | D14: Food | E14: Offline | F14: Low | G14: 44939 | H14: 133 | I14: 25.17 | J14: 157.64 | K14: =H14*I14 -> 3347.61
A15: ORD0014 | B15: East | C15: USA | D15: Food | E15: Offline | F15: Low | G15: 44940 | H15: 472 | I15: 86.18 | J15: 201.46 | K15: =H15*I15 -> 40676.96 | L15: Total Records: | M15: 350
A16: ORD0015 | B16: West | C16: India | D16: Beverages | E16: Offline | F16: Low | G16: 44941 | H16: 47 | I16: 222.11 | J16: 160.08 | K16: =H16*I16 -> 10439.17 | L16: Total Missing Values: | M16: 40
A17: ORD0016 | B17: North | C17: Germany | D17: Electronics | E17: Online | F17: High | G17: 44942 | H17: 337 | I17: 363.79 | J17: 216.81 | K17: =H17*I17 -> 122597.23
A18: ORD0017 | B18: West | C18: Germany | D18: Electronics | E18: Online | F18: High | G18: 44943 | H18: 260 | I18: 298.67 | J18: 251.92 | K18: =H18*I18 -> 77654.2 | L18: Detailed Missing Values by Row
A19: ORD0018 | B19: West | C19: India | D19: Clothing | E19: Offline | F19: Medium | G19: 44944 | H19: 398 | I19: 326.9 | J19: 270.37 | K19: =H19*I19 -> 130106.2
A20: ORD0019 | B20: West | C20: USA | D20: Beverages | E20: Online | F20: Medium | G20: 44945 | H20: 185 | I20: 242.24 | J20: 213.93 | K20: =H20*I20 -> 44814.4 | L20: Column | M20: Row Numbers with Missing Values
A21: ORD0020 | B21: East | C21: India | D21: Food | E21: Offline | F21: High | G21: 44946 | H21: 99 | I21: 309.79 | J21: 289.13 | K21: =H21*I21 -> 30669.21 | L21: Region | M21: 11, 19, 32, 51, 65, 119, 123, 223, 333, 348
A22: ORD0021 | B22: South | C22: Germany | D22: Electronics | E22: Offline | F22: Medium | G22: 44947 | H22: 411 | I22: 167.86 | J22: 58.23 | K22: =H22*I22 -> 68990.46 | L22: Category | M22: 26, 160, 212, 254, 265, 285, 307, 308, 309, 325
A23: ORD0022 | B23: North | C23: Australia | D23: Food | E23: Offline | F23: High | G23: 44948 | H23: 463 | I23: 237.74 | J23: 86.37 | K23: =H23*I23 -> 110073.62 | L23: Units Sold | M23: 40, 132, 201, 229, 252, 290, 295, 315, 318, 329
A24: ORD0023 | B24: South | C24: Australia | D24: Electronics | E24: Online | F24: Low | G24: 44949 | H24: 46 | I24: 373.42 | J24: 327.86 | K24: =H24*I24 -> 17177.32 | L24: Unit Price | M24: 29, 38, 46, 81, 93, 158, 258, 262, 289, 309
A25: ORD0024 | B25: West | C25: UK | D25: Electronics | E25: Offline | F25: Medium | G25: 44950 | H25: 325 | I25: 436.56 | J25: 130.37 | K25: =H25*I25 -> 141882
A26: ORD0025 | B26: West | C26: India | D26: Beverages | E26: Offline | F26: Medium | G26: 44951 | H26: 185 | I26: 219.66 | J26: 11.11 | K26: =H26*I26 -> 40637.1
A27: ORD0026 | B27: South | C27: India | D27: Beverages | E27: Offline | F27: High | G27: 44952 | H27: 470 | I27: 26.61 | J27: 63.21 | K27: =H27*I27 -> 12506.7 | L27: Total Price for ORD0123: | M27: =_xlfn.XLOOKUP("ORD0123",A2:A351,K2:K351,"Not Found") -> 15849.3
A28: ORD0027 | B28: South | C28: UK | D28: Furniture | E28: Online | F28: Medium | G28: 44953 | H28: 293 | I28: 85.03 | J28: 91 | K28: =H28*I28 -> 24913.79
A29: ORD0028 | B29: South | C29: UK | D29: Food | E29: Online | F29: Medium | G29: 44954 | H29: 462 | I29: 249.65 | J29: 383.01 | K29: =H29*I29 -> 115338.3 | L29: Order Details for ORD0123:
A30: ORD0029 | B30: West | C30: UK | D30: Beverages | E30: Offline | F30: Low | G30: 44955 | H30: 470 | I30: 328.37 | J30: 230.07 | K30: =H30*I30 -> 154333.9 | L30: Units Sold: | M30: =_xlfn.XLOOKUP("ORD0123",A2:A351,H2:H351) -> 46
A31: ORD0030 | B31: West | C31: Germany | D31: Beverages | E31: Online | F31: Medium | G31: 44956 | H31: 90 | I31: 169.5 | J31: 373.23 | K31: =H31*I31 -> 15255 | L31: Unit Price: | M31: =_xlfn.XLOOKUP("ORD0123",A2:A351,I2:I351) -> 344.55
A32: ORD0031 | B32: West | C32: India | D32: Beverages | E32: Online | F32: Low | G32: 44957 | H32: 123 | I32: 273.53 | J32: 230.92 | K32: =H32*I32 -> 33644.19 | L32: Formula: | M32: =_xlfn.XLOOKUP("ORD0123",A2:A351,H2:H351) & " × " & _xlfn.XLOOKUP("ORD0123",A2:A351,I2:I351) -> 46 × 344.55
A33: ORD0032 | B33: North | C33: Germany | D33: Beverages | E33: Online | F33: High | G33: 44958 | H33: 49 | I33: 249.17 | J33: 192.78 | K33: =H33*I33 -> 12209.33 | L33: Total Revenue: | M33: =_xlfn.XLOOKUP("ORD0123",A2:A351,K2:K351) -> 15849.3
A34: ORD0033 | B34: West | C34: UK | D34: Beverages | E34: Online | F34: Medium | G34: 44959 | H34: 310 | I34: 45.36 | J34: 126.86 | K34: =H34*I34 -> 14061.6
A35: ORD0034 | B35: South | C35: India | D35: Clothing | E35: Online | F35: Low | G35: 44960 | H35: 233 | I35: 204.61 | J35: 243.34 | K35: =H35*I35 -> 47674.13
A36: ORD0035 | B36: South | C36: Germany | D36: Food | E36: Online | F36: High | G36: 44961 | H36: 327 | I36: 114.18 | J36: 57.4 | K36: =H36*I36 -> 37336.86
A37: ORD0036 | B37: North | C37: Germany | D37: Beverages | E37: Online | F37: Medium | G37: 44962 | H37: 358 | I37: 212.11 | J37: 359.51 | K37: =H37*I37 -> 75935.38
A38: ORD0037 | B38: West | C38: UK | D38: Food | E38: Online | F38: High | G38: 44963 | H38: 124 | I38: 249.65 | J38: 332.07 | K38: =H38*I38 -> 30956.6
A39: ORD0038 | B39: North | C39: India | D39: Clothing | E39: Online | F39: Medium | G39: 44964 | H39: 195 | I39: 421.02 | J39: 128.38 | K39: =H39*I39 -> 82098.9
A40: ORD0039 | B40: North | C40: UK | D40: Clothing | E40: Online | F40: High | G40: 44965 | H40: 256 | I40: 91.23 | J40: 381.21 | K40: =H40*I40 -> 23354.88
...

Sheet Pivot_Analysis
A1: Pivot Table: Total Sales by Category and Region
A3: Sum of Total Revenue | B3: Column Labels
A4: Row Labels | B4: East | C4: North | D4: South | E4: West | F4: Grand Total
A5: Beverages | B5: 1110756.7 | C5: 1276139.2 | D5: 1199638.5 | E5: 1977673.9 | F5: 5564208.3
A6: Clothing | B6: 1587309.5 | C6: 629683.34 | D6: 496502.89 | E6: 1133989.7 | F6: 3847485.5
A7: Electronics | B7: 946379.68 | C7: 950484.27 | D7: 1068359 | E7: 1557978.1 | F7: 4523201.1
A8: Food | B8: 886874.81 | C8: 1658465.6 | D8: 695855.68 | E8: 823913.15 | F8: 4065109.2
A9: Furniture | B9: 1764289.8 | C9: 731274.15 | D9: 832820.25 | E9: 1131299.3 | F9: 4459683.6
A10: Grand Total | B10: 6295610.5 | C10: 5246046.6 | D10: 4293176.3 | E10: 6624854.3 | F10: 22459688

Sheet Dashboard
A1: 📊 RETAIL SALES DASHBOARD
A3: KEY PERFORMANCE INDICATORS
A4: 💰 Total Revenue | C4: 📦 Total Units Sold | E4: 📈 Total Profit | G4: 🛒 Total Orders | I4: 💵 Avg Order Value
A5: =TEXT(SUM(Retail_Dataset!K2:K351),"$#,##0") -> $22,459,688 | C5: =TEXT(SUM(Retail_Dataset!H2:H351),"#,##0") -> 89,567 | E5: {=TEXT(SUMPRODUCT((Retail_Dataset!I2:I351-Retail_Dataset!J2:J351)*Retail_Dataset!H2:H351),"$#,##0")} -> $5,069,192 | G5: =COUNTA(Retail_Dataset!A2:A351) -> 350 | I5: =TEXT(AVERAGE(Retail_Dataset!K2:K351),"$#,##0") -> $64,171
A7: ADDITIONAL METRICS
A8: Top Region: | B8: {=INDEX(Retail_Dataset!B2:B351,MATCH(MAX(SUMIF(Retail_Dataset!B2:B351,Retail_Dataset!B2:B351,Retail_Dataset!K2:K351)),SUMIF(Retail_Dataset!B2:B351,Retail_Dataset!B2:B351,Retail_Dataset!K2:K351),0))} -> West | C8: Top Category: | D8: {=INDEX(Retail_Dataset!D2:D351,MATCH(MAX(SUMIF(Retail_Dataset!D2:D351,Retail_Dataset!D2:D351,Retail_Dataset!K2:K351)),SUMIF(Retail_Dataset!D2:D351,Retail_Dataset!D2:D351,Retail_Dataset!K2:K351),0))} -> Beverages | E8: Avg Profit/Order: | F8: {=TEXT(SUMPRODUCT((Retail_Dataset!I2:I351-Retail_Dataset!J2:J351)*Retail_Dataset!H2:H351)/COUNTA(Retail_Dataset!A2:A351),"$#,##0")} -> $14,483 | G8: Top Country: | H8: {=INDEX(Retail_Dataset!C2:C351,MATCH(MAX(SUMIF(Retail_Dataset!C2:C351,Retail_Dataset!C2:C351,Retail_Dataset!K2:K351)),SUMIF(Retail_Dataset!C2:C351,Retail_Dataset!C2:C351,Retail_Dataset!K2:K351),0))} -> India | I8: Profit Margin: | J8: {=TEXT(SUMPRODUCT((Retail_Dataset!I2:I351-Retail_Dataset!J2:J351)*Retail_Dataset!H2:H351)/SUM(Retail_Dataset!K2:K351),"0.0%")} -> 22.6%
A10: VISUAL ANALYTICS
A11: 📊 CHARTS
A28: Data Source: Retail_Dataset | 350 Orders | Last Updated: Formulas auto-refresh
A30: Region | B30: Revenue | D30: Category | E30: Revenue | G30: Channel | H30: Revenue | J30: Priority | K30: Orders
A31: East | B31: =SUMIF(Retail_Dataset!B:B,A31,Retail_Dataset!K:K) -> 6295610.5 | D31: Beverages | E31: =SUMIF(Retail_Dataset!D:D,D31,Retail_Dataset!K:K) -> 5564208.3 | G31: Online | H31: =SUMIF(Retail_Dataset!E:E,G31,Retail_Dataset!K:K) -> 12339579 | J31: High | K31: =COUNTIF(Retail_Dataset!F:F,J31) -> 125
A32: North | B32: =SUMIF(Retail_Dataset!B:B,A32,Retail_Dataset!K:K) -> 5246046.6 | D32: Clothing | E32: =SUMIF(Retail_Dataset!D:D,D32,Retail_Dataset!K:K) -> 3847485.5 | G32: Offline | H32: =SUMIF(Retail_Dataset!E:E,G32,Retail_Dataset!K:K) -> 10120109 | J32: Medium | K32: =COUNTIF(Retail_Dataset!F:F,J32) -> 116
A33: South | B33: =SUMIF(Retail_Dataset!B:B,A33,Retail_Dataset!K:K) -> 4293176.3 | D33: Electronics | E33: =SUMIF(Retail_Dataset!D:D,D33,Retail_Dataset!K:K) -> 4523201.1 | J33: Low | K33: =COUNTIF(Retail_Dataset!F:F,J33) -> 109
A34: West | B34: =SUMIF(Retail_Dataset!B:B,A34,Retail_Dataset!K:K) -> 6624854.3 | D34: Food | E34: =SUMIF(Retail_Dataset!D:D,D34,Retail_Dataset!K:K) -> 4065109.2
D35: Furniture | E35: =SUMIF(Retail_Dataset!D:D,D35,Retail_Dataset!K:K) -> 4459683.6

Sheet Summary_Report
A1: 📋 RETAIL SALES SUMMARY REPORT
A2: ="Report Generated: "&TEXT(TODAY(),"MMMM DD, YYYY") -> Report Generated: July 22, 2026
A4: 1. EXECUTIVE SUMMARY
A5: Metric | B5: Value
A6: Total Orders | B6: =COUNTA(Retail_Dataset!A2:A351) -> 350
A7: Total Revenue | B7: =SUM(Retail_Dataset!K2:K351) -> 22459688
A8: Total Units Sold | B8: =SUM(Retail_Dataset!H2:H351) -> 89567
A9: Total Profit | B9: {=SUMPRODUCT((Retail_Dataset!I2:I351-Retail_Dataset!J2:J351)*Retail_Dataset!H2:H351)} -> 5069192.1
A10: Profit Margin | B10: =B9/B7 -> 0.22570181
A11: Average Order Value | B11: =AVERAGE(Retail_Dataset!K2:K351) -> 64170.536
A12: Average Units per Order | B12: =AVERAGE(Retail_Dataset!H2:H351) -> 255.90571
